<?xml version="1.0" encoding="UTF-8"?>
<testng-results skipped="0" failed="1" total="2" passed="1">
  <reporter-output>
  </reporter-output>
  <suite name="Default suite" duration-ms="39" started-at="2018-07-19T10:04:18Z" finished-at="2018-07-19T10:04:18Z">
    <groups>
    </groups>
    <test name="Default test" duration-ms="39" started-at="2018-07-19T10:04:18Z" finished-at="2018-07-19T10:04:18Z">
      <class name="Assertion.Hard">
        <test-method status="FAIL" signature="CreateCustomerTest()[pri:0, instance:Assertion.Hard@4520ebad]" name="CreateCustomerTest" duration-ms="17" started-at="2018-07-19T15:34:18Z" finished-at="2018-07-19T15:34:18Z">
          <exception class="java.lang.AssertionError">
            <message>
              <![CDATA[expected [Acti] but found [Actitime]]]>
            </message>
            <full-stacktrace>
              <![CDATA[java.lang.AssertionError: expected [Acti] but found [Actitime]
	at org.testng.Assert.fail(Assert.java:94)
	at org.testng.Assert.failNotEquals(Assert.java:496)
	at org.testng.Assert.assertEquals(Assert.java:125)
	at org.testng.Assert.assertEquals(Assert.java:178)
	at org.testng.Assert.assertEquals(Assert.java:188)
	at Assertion.Hard.CreateCustomerTest(Hard.java:14)
	at sun.reflect.NativeMethodAccessorImpl.invoke0(Native Method)
	at sun.reflect.NativeMethodAccessorImpl.invoke(NativeMethodAccessorImpl.java:62)
	at sun.reflect.DelegatingMethodAccessorImpl.invoke(DelegatingMethodAccessorImpl.java:43)
	at java.lang.reflect.Method.invoke(Method.java:498)
	at org.testng.internal.MethodInvocationHelper.invokeMethod(MethodInvocationHelper.java:85)
	at org.testng.internal.Invoker.invokeMethod(Invoker.java:639)
	at org.testng.internal.Invoker.invokeTestMethod(Invoker.java:816)
	at org.testng.internal.Invoker.invokeTestMethods(Invoker.java:1124)
	at org.testng.internal.TestMethodWorker.invokeTestMethods(TestMethodWorker.java:125)
	at org.testng.internal.TestMethodWorker.run(TestMethodWorker.java:108)
	at org.testng.TestRunner.privateRun(TestRunner.java:774)
	at org.testng.TestRunner.run(TestRunner.java:624)
	at org.testng.SuiteRunner.runTest(SuiteRunner.java:359)
	at org.testng.SuiteRunner.runSequentially(SuiteRunner.java:354)
	at org.testng.SuiteRunner.privateRun(SuiteRunner.java:312)
	at org.testng.SuiteRunner.run(SuiteRunner.java:261)
	at org.testng.SuiteRunnerWorker.runSuite(SuiteRunnerWorker.java:52)
	at org.testng.SuiteRunnerWorker.run(SuiteRunnerWorker.java:86)
	at org.testng.TestNG.runSuitesSequentially(TestNG.java:1215)
	at org.testng.TestNG.runSuitesLocally(TestNG.java:1140)
	at org.testng.TestNG.run(TestNG.java:1048)
	at org.testng.remote.AbstractRemoteTestNG.run(AbstractRemoteTestNG.java:114)
	at org.testng.remote.RemoteTestNG.initAndRun(RemoteTestNG.java:251)
	at org.testng.remote.RemoteTestNG.main(RemoteTestNG.java:77)
]]>
            </full-stacktrace>
          </exception> <!-- java.lang.AssertionError -->
          <reporter-output>
          </reporter-output>
        </test-method> <!-- CreateCustomerTest -->
        <test-method status="PASS" signature="modifyCustomerTest()[pri:0, instance:Assertion.Hard@4520ebad]" name="modifyCustomerTest" duration-ms="2" started-at="2018-07-19T15:34:18Z" finished-at="2018-07-19T15:34:18Z">
          <reporter-output>
          </reporter-output>
        </test-method> <!-- modifyCustomerTest -->
      </class> <!-- Assertion.Hard -->
    </test> <!-- Default test -->
  </suite> <!-- Default suite -->
</testng-results>
